Workbook

Sheet README
A1: Regional Climate & Weather Event Register — Catskills / Hudson Valley / Capital Region
A2: Reference point for the Wind & Tornado sheet: Westerlo, NY hamlet
A3: Westerlo latitude | B3: 42.517
A4: Westerlo longitude | B4: -74.045
A5: Search radius (miles) | B5: 30
A6: Radius note: the 30-mile radius applies ONLY to the Wind & Tornado sheet (localized, small-footprint events). Regional hazards — floods, ice jams, droughts, cold waves, blizzards, heat waves — are NOT radius-limited; they are included wherever they affected the Catskills, Hudson Valley, Mohawk Valley or Capital Region. The CRREL ice-jam sheet uses a 75-mile regional footprint with its own Dist. column.
A8: Sheets
A9: Events | B9: One row per event. ~150 rows. Sort/filter by Category, Confidence, Verified.
A10: Wind & Tornadoes | B10: Every tornado from NCEI (1950–2012 via Tornado Project; 2013+ via NWS ALY surveys/tornadopath) within ~45 mi, plus Grazulis pre-1950 F2+/deadly, plus notable straight-line wind days. Distance from Westerlo is a live haversine formula off the cells above; 'Within radius' flag recalculates if you change the radius.
A11: Summary | B11: COUNTIF roll-ups by category, confidence and century; tornado counts by rating and within-radius.
A12: Sources | B12: Primary sources with URLs and what each is good for.
A14: Confidence grades
A15: A | B15: Instrument-era figure taken directly from NWS Albany, NCEI, USGS, or an NWS storm survey this pass.
A16: B | B16: Well-documented event; figures from secondary sources or from memory of standard references — check before quoting a number.
A17: C | B17: Chronicle/diary-era (pre-~1870) or qualitative; treat as 'it happened and was bad', not as data.
A19: Verified column | B19: Y = checked against a primary source during this build (NWS ALY Past Events page, Tornado Project county tables, NCEI, NWS ALY July 2026 writeup). N = not yet checked; these are the rows to work through first.
A21: Known gaps / to-do
A22: 1 | B22: Pre-1870 growing-season disasters are under-represented; Ludlum and county histories (Beers, Munsell's Annals of Albany) would fill them.
A23: 2 | B23: Albany all-time extremes (104°F Jul 4 1911; –28°F Jan 19 1971) not yet re-checked against weather.gov/media/aly/Climate/ALB_Extremes.pdf.
A24: 3 | B24: Post-2012 tornado coordinates marked 'approx' should be replaced with NCEI begin/end lat-lon.
A25: 4 | B25: April 21, 2021 tornado locations and the July 27, 2014 EF1 location not captured.
A26: 5 | B26: Frost/freeze dates for the Helderberg plateau specifically: pull GHCN daily for the nearest coop (Rensselaerville? Delanson? Albany AP as fallback) rather than trusting valley stations.
A27: 6 | B27: Drought years should be re-graded from the US Drought Monitor archive (2000+) and Palmer indices (pre-2000).
A29: Timeline anchors | B29: Columns Q–V on Events give one anchor date per row for plotting. Precision: day = the date is the date; days = anchored to the first (or peak) day of a ≤10-day event; week/month/season/year = a representative point inside a longer window (mid-point unless the basis column says otherwise). Filter on precision when you build the timeline so you don't plot a drought as if it happened on one afternoon.
A30: Dates before 1900 | B30: Excel cannot store dates before 1900-01-01, so all dates are ISO text and the anchor is split into numeric Year/Month/Day columns — the format TimelineJS and most timeline libraries expect.
A31: Geohazard rows | B31: Categories Ice jam, Landslide, Sinkhole (karst vs infrastructure) added. Two rows are context/pattern rows (precision = year) and should be filtered out of a point timeline. Three Niagara rows are flagged OUT OF REGION in the name.
A32: Cells highlighted yellow are inputs you can change.
A34: --- 2026-09-21 addendum (Claude, atlas session — the original research chat was NOT reopened) ---
A35: Cross-checked this handoff package against the atlas's own copy of the register: the atlas copy was already ahead (293 events / 29 sources / 29 karst features vs 264/24/24 here), so nothing was missing.
A36: Then worked the open-items list as far as web search + the atlas's own station data would go:
A37: #1 Knox Cave month: the 2025 Pomeroy Foundation historic marker independently says March 1975 — now 2 sources for March vs 1 for May vs 1 for 1976. Anchor updated to 1975-03 (month precision; day still not asserted). See Events row 141 and Sources.
A38: #3 Albany extremes: CONFIRMED against the current ALB_Extremes.pdf — 104°F Jul 4 1911 / -28°F Jan 19 1971, exactly as already recorded.
A39: #4 Frost/freeze phenology: built from Alcove Dam's own daily record (already in the atlas repo, no new upload needed) — see the new "Frost & Freeze Phenology" sheet. 70-year and recent-30-year medians, full year-by-year table. Alcove Dam is ~590 ft, ~1,100 ft below Laurie's plateau — the best available regional anchor, not a plateau substitute.
A40: Bonus: Stone (2005 NCKMS) corrects McFail's own death to July 1, 1854 (not the widely repeated 1853 from Roscoe 1882) — logged in Sources. Did NOT find the historic-entrance collapse date (#2) — still open.
A41: STILL OPEN, genuinely unresolved by this pass (need the original chat's archive access or Laurie's own future work, not just web search):
A42: #2 McFails historic-entrance collapse date. #5 Ludlum vol. II (1821-1870) — a physical/scanned book, not found online. #6 Fine-grained LiDAR sinkholes off Laurie's own parcel DEM — her own QGIS work (see the separate Westerlo_land_mapping package, which already ran this on her 25 acres and found NO karst there — see data/hilltowns_poi_lore_notes.md). #7 NYS Museum karst inventory / USGS SIR 2020-5030 Appendix 1 — not ingested. #8 Post-2012 tornado exact coordinates — would need the row-by-row NCEI lookup, not attempted this pass.
A43: The Folklore doc's lore items (Knox Cave legends, Old Skull bone-chamber, Clarksville wall carvings, Barton Hill "hollow hill") were appended to data/hilltowns_poi_lore_notes.md for the Lore Map — kept OUT of this register per the original project's own convention.
A45: --- 2026-09-21 addendum #2 (Claude, atlas session) ---
... A48: v2 did NOT carry my Knox Cave date fix or the 4 new sources forward — those stay atlas-only unless the original chat is refreshed from here.

Sheet Events
A1: ID | B1: Start date | C1: End date | D1: Year | E1: Century | F1: Category | G1: Event name | H1: Area affected | I1: Key measurement | J1: Station / gauge | K1: Impact summary | L1: Primary source | M1: Source URL | N1: Confidence | O1: Verified this pass | P1: Notes / to-do | Q1: Timeline anchor (ISO) | R1: Anchor year | S1: Anchor month | T1: Anchor day | U1: Date precision | V1: Anchor basis | W1: Show on timeline
A2: 1 | B2: 1635-08-25 | C2: 1635-08-25 | D2: =VALUE(LEFT(B2,4)) | E2: =INT((D2-1)/100)+1 | F2: Tropical cyclone | G2: The Great Colonial Hurricane of 1635 | H2: New England; track inland over W. New England / NY State | I2: Trough of low pressure over W. New England or NY State drove the storm north; forests leveled, hundreds of thousands of trees down | J2: Winthrop & Bradford diaries via Ludlum | K2: The greatest NE hurricane of the colonial period; Mather inferred a well-established low-pressure trough over western New England or NY State. Aug 15 Old Style = Aug 25 New Style. | L2: Ludlum, Early American Hurricanes 1492–1870 (AMS, 1963), pp. 8–23 (verified, page images/text) | M2: https://hdl.handle.net/2027/mdp.39015002912718 | N2: C | O2: Y | P2: Track inland of NY State inferred, not observed at Albany; included as the regional-scale storm-of-record for the 17th c. | Q2: 1635-08-25 | R2: =VALUE(LEFT(Q2,4)) | S2: =VALUE(MID(Q2,6,2)) | T2: =VALUE(RIGHT(Q2,2)) | U2: day | V2: Single-day event
A3: 2 | B3: 1645-11-25 | C3: 1645-11-25 | D3: =VALUE(LEFT(B3,4)) | E3: =INT((D3-1)/100)+1 | F3: Early freeze | G3: Hudson closed at Rensselaerwyck, Nov 25, 1645 | H3: Albany (Rensselaerwyck) | I3: North River closed Nov 25 'and remained frozen very late' | J3: Van der Donck, Description of New Netherland (1656) via Ludlum p. 28 | K3: Earliest dated weather observation for the Albany area in the register; van der Donck notes winters above the Highlands begin earlier and last longer than at New Amsterdam. | L3: Ludlum, Early American Winters I (page screenshots, verified) | N3: B | O3: Y | P3: Old Style date as given. | Q3: 1645-11-25 | R3: =VALUE(LEFT(Q3,4)) | S3: =VALUE(MID(Q3,6,2)) | T3: =VALUE(RIGHT(Q3,2)) | U3: day | V3: Single-day event
A4: 3 | B4: 1667-08-27 | C4: 1667-08-27 | D4: =VALUE(LEFT(B4,4)) | E4: =INT((D4-1)/100)+1 | F4: Tropical cyclone | G4: The Dreadful Hurry Cane of 1667 | H4: Virginia; track inland over the Middle Atlantic; Manhattan Aug 29 | I4: Severe storm at Manhattan Aug 29 (Stokes, Iconography); center inland over N. Virginia then up the seaboard | J4: Strange News from Virginia (1667) via Ludlum | K4: Reached Manhattan; the northern edge likely brushed the lower Hudson. 12 days of rain and flooding followed in VA. | L4: Ludlum, Early American Hurricanes 1492–1870 (AMS, 1963), pp. 8–23 (verified, page images/text) | M4: https://hdl.handle.net/2027/mdp.39015002912718 | N4: C | O4: N | P4: Manhattan hit confirmed; Hudson Valley extent inferred. | Q4: 1667-08-27 | R4: =VALUE(LEFT(Q4,4)) | S4: =VALUE(MID(Q4,6,2)) | T4: =VALUE(RIGHT(Q4,2)) | U4: day | V4: Single-day event
A5: 4 | B5: 1683-08-23 | C5: 1683-08-23 | D5: =VALUE(LEFT(B5,4)) | E5: =INT((D5-1)/100)+1 | F5: Tropical cyclone / flood | G5: Hurricane and Connecticut Valley flood of 1683 | H5: Connecticut Valley / Long Island Sound | I5: Connecticut River rose 26 ft at Wethersfield (Aug 13 Old Style); four river towns (Windsor, Hartford, Wethersfield, Middletown) devastated; corn destroyed | J5: Increase Mather, Remarkable Providences (1684) via Ludlum | K5: Major Connecticut Valley freshet from a hurricane; the closest 17th-c. flood to the register's eastern edge. | L5: Ludlum, Early American Hurricanes 1492–1870 (AMS, 1963), pp. 8–23 (verified, page images/text) | M5: https://hdl.handle.net/2027/mdp.39015002912718 | N5: C | O5: Y | P5: CT Valley, ~east of the register core; Aug 13 O.S. = Aug 23 N.S. | Q5: 1683-08-23 | R5: =VALUE(LEFT(Q5,4)) | S5: =VALUE(MID(Q5,6,2)) | T5: =VALUE(RIGHT(Q5,2)) | U5: day | V5: Single-day event
A6: 5 | B6: 1697-12-01 | C6: 1698-04-15 | D6: =VALUE(LEFT(B6,4)) | E6: =INT((D6-1)/100)+1 | F6: Cold winter | G6: Severest winter in memory, 1697–98 | H6: Albany / Schenectady / New England | I6: Snow 'deeper than the height of a man'; 26 snows at Dorchester | J6: Earl of Bellomont to Board of Trade, 28 Oct 1698, via Ludlum p. 18 | K6: Bellomont: had the winter not been so severe 'the French would certainly have destroyed both Albany and Schenectady' – a planned invasion on 1,500 pairs of snowshoes from Montreal was abandoned. Peter Kalm 50 years later: everyone still called it the coldest ever felt. | L6: Ludlum, Early American Winters I (page screenshots, verified) | N6: B | O6: Y | P6: Season row; a military-history cross-reference for the Hilltowns. | Q6: 1698-02-15 | R6: =VALUE(LEFT(Q6,4)) | S6: =VALUE(MID(Q6,6,2)) | T6: =VALUE(RIGHT(Q6,2)) | U6: season | V6: Mid-winter; Bellomont letter gives no days
A7: 6 | B7: 1705-12-30 | C7: 1706-01-02 | D7: =VALUE(LEFT(B7,4)) | E7: =INT((D7-1)/100)+1 | F7: Arctic outbreak / river ice | G7: Christmas 1705 cold wave – Hudson frozen at NYC | H7: NYC / lower Hudson | I7: 'Coldest that was ever felt here'; Hudson froze over completely and stayed fast several days; severest cold lasted 3 days | J7: Boston News-Letter 21 Jan 1706 via Ludlum pp. 42, 77 | K7: Sloop-of-war grounded off Sandy Hook; 132 crew froze to death. | L7: Ludlum, Early American Winters I (page screenshots, verified) | N7: B | O7: Y | P7: Onset Dec 30 New Style (= Christmas Old Style). | Q7: 1705-12-30 | R7: =VALUE(LEFT(Q7,4)) | S7: =VALUE(MID(Q7,6,2)) | T7: =VALUE(RIGHT(Q7,2)) | U7: days | V7: Multi-day event; anchored to first day
A8: 7 | B8: 1706-10-14 | C8: 1706-10-16 | D8: =VALUE(LEFT(B8,4)) | E8: =INT((D8-1)/100)+1 | F8: Rain flood | G8: October 1706 flood at Albany | H8: Albany / Rensselaer / Connecticut Valley | I8: 'The greatest Flood there that ever was known'; Rensselaers Island 6 ft under water, low lands drowned (Boston News-Letter 28 Oct 1706); CT River flood, ~1000 loads of hay lost | J8: Boston News-Letter, 28 Oct 1706, via Ludlum p. 20 | K8: A DIRECT Albany flood record: mid-October 1706 rain + a hard gale caused the greatest flood then known at Albany. Rare early instrumental-adjacent Albany event. | L8: Ludlum, Early American Hurricanes 1492–1870 (AMS, 1963), pp. 8–23 (verified, page images/text) | M8: https://hdl.handle.net/2027/mdp.39015002912718 | N8: B | O8: Y | P8: Genuine Albany flood-of-record notice for its time; the standout row from this batch. | Q8: 1706-10-14 | R8: =VALUE(LEFT(Q8,4)) | S8: =VALUE(MID(Q8,6,2)) | T8: =VALUE(RIGHT(Q8,2)) | U8: days | V8: Rain Oct 14–16; anchored to first day
A9: 8 | B9: 1717-02-27 | C9: 1717-03-07 | D9: =VALUE(LEFT(B9,4)) | E9: =INT((D9-1)/100)+1 | F9: Snowstorm | G9: The Great Snow of 1717 | H9: New England / Hudson Valley (Philadelphia 'a great snow') | I9: Four storms: Feb 27, Mar 1, Mar 4 ('4 foot deep in ye woods on a level', drifts 10–12 ft), Mar 7; cattle and horses dead in the storm | J9: Hempstead diary (New London), Sewall, Mather via Ludlum pp. 42–43 | K9: Northeasters that also reached Philadelphia (river full of ice); no Albany-specific report in Ludlum. | L9: Ludlum, Early American Winters I (page screenshots, verified) | N9: B | O9: Y | P9: Hudson Valley depth not documented – Annals of Albany may have it. | Q9: 1717-03-07 | R9: =VALUE(LEFT(Q9,4)) | S9: =VALUE(MID(Q9,6,2)) | T9: =VALUE(RIGHT(Q9,2)) | U9: days | V9: Final and heaviest storm of the series
A10: 9 | B10: 1740-11-15 | C10: 1741-04-15 | D10: =VALUE(LEFT(B10,4)) | E10: =INT((D10-1)/100)+1 | F10: Cold winter | G10: Hard Winter of 1740–41 | H10: Hudson Valley / New England | I10: Hudson at NYC shut to navigation twice: after the storm of Dec 28, 1740 until Jan 21, 1741, and again the 2nd–3rd weeks of Feb 1741; Stiles estimated ~−8°F; 27–30 distinct snows; snow 3 ft on the level at Newbury Mar 17; ice held to mid-April | J10: Ludlum pp. 50–53 (Hempstead diary, Coffin, Boston News-Letter) | K10: Winter set in Nov 15 (Newbury); Dec 3 rain for three weeks → biggest CT River flood in 50 years; mid-December 'prodigious storm' with eaves not dripping for 30 days; half the cattle, horses and 2/3 of goats died of scarcity in Connecticut. | L10: Ludlum, Early American Winters I (page screenshots, verified) | N10: B | O10: Y | P10: Now day-anchored. Stiles (1780) judged 1780 snowier than 1740/41. | Q10: 1740-12-28 | R10: =VALUE(LEFT(Q10,4)) | S10: =VALUE(MID(Q10,6,2)) | T10: =VALUE(RIGHT(Q10,2)) | U10: day | V10: Storm that closed the Hudson at NYC
A11: 10 | B11: 1741-02-08 | C11: 1741-02-09 | D11: =VALUE(LEFT(B11,4)) | E11: =INT((D11-1)/100)+1 | F11: Nor'easter | G11: Great NE storm of Feb 8–9, 1741 | H11: Boston / New England | I11: 'Snow higher than has been known since the vast snow of Feb 19, 1716/17' (Boston News-Letter) | J11: Ludlum p. 50 | K11: One of two February 1741 storms singled out by the press. | L11: Ludlum, Early American Winters I (page screenshots, verified) | N11: B | O11: Y | P11: Hudson Valley extent not stated. | Q11: 1741-02-08 | R11: =VALUE(LEFT(Q11,4)) | S11: =VALUE(MID(Q11,6,2)) | T11: =VALUE(RIGHT(Q11,2)) | U11: days | V11: Multi-day event; anchored to first day
A12: 11 | B12: 1741-04-01 | C12: 1741-04-01 | D12: =VALUE(LEFT(B12,4)) | E12: =INT((D12-1)/100)+1 | F12: River ice (late) | G12: Hudson at Esopus bearing loaded teams, April 1, 1741 | H12: Kingston (Esopus) | I12: Loaded teams crossed the Hudson on the ice Apr 1; CT River crossed on horseback Apr 11 | J12: Ludlum p. 52 | K12: Latest documented heavy-load ice crossing of the Hudson in the register; sleighs at Deerfield to Apr 10. | L12: Ludlum, Early American Winters I (page screenshots, verified) | N12: B | O12: Y | P12: Directly relevant to Hudson Valley ice phenology. | Q12: 1741-04-01 | R12: =VALUE(LEFT(Q12,4)) | S12: =VALUE(MID(Q12,6,2)) | T12: =VALUE(RIGHT(Q12,2)) | U12: day | V12: Single-day event
A13: 12 | B13: 1764-12-25 | C13: 1764-12-26 | D13: =VALUE(LEFT(B13,4)) | E13: =INT((D13-1)/100)+1 | F13: Coastal storm | G13: Christmas Night storm of 1764 | H13: Entire Atlantic coast incl. NYC | I13: Began ~2000 Dec 25, snow → rain; Philadelphia 'violent windstorm and snow'; NYC strong wind and much snow | J13: Ludlum pp. 60–61 | K13: Opened the severe winter of 1764–65, 'snowiest since 1748, coldest since 1741'; Delaware clogged with ice. | L13: Ludlum, Early American Winters I (page screenshots, verified) | N13: B | O13: Y | Q13: 1764-12-25 | R13: =VALUE(LEFT(Q13,4)) | S13: =VALUE(MID(Q13,6,2)) | T13: =VALUE(RIGHT(Q13,2)) | U13: days | V13: Multi-day event; anchored to first day
A14: 13 | B14: 1765-01-26 | C14: 1765-01-28 | D14: =VALUE(LEFT(B14,4)) | E14: =INT((D14-1)/100)+1 | F14: Arctic outbreak / river ice | G14: January 1765 deep freeze – Hudson nearly solid at NYC | H14: NYC / lower Hudson | I14: Kings College thermometer at or below zero 57 hours until 1400 Jan 28, est. low −6°F; Hudson froze 'almost solid' to the Jersey shore; NYC Feb 11: 'six weeks in Greenland, ground covered near three feet' | J14: Ludlum p. 61 (Watts letter book) | K14: Longest sub-zero spell in NYC history if authentic; a traveller walking to Jersey fell through 350 yd from shore. | L14: Ludlum, Early American Winters I (page screenshots, verified) | N14: B | O14: Y | Q14: 1765-01-26 | R14: =VALUE(LEFT(Q14,4)) | S14: =VALUE(MID(Q14,6,2)) | T14: =VALUE(RIGHT(Q14,2)) | U14: days | V14: Multi-day event; anchored to first day
A15: 14 | B15: 1769-09-08 | C15: 1769-09-08 | D15: =VALUE(LEFT(B15,4)) | E15: =INT((D15-1)/100)+1 | F15: Tropical cyclone | G15: September 1769 hurricane – NYC & Hudson Valley | H15: NYC / New Brunswick NJ / lower Hudson | I15: NYC swept by a violent NE gale continuing past 2000, trees torn up and corn damaged; New Brunswick NJ severe (trees down, bridges carried away) | J15: Ludlum p. 25 (Va. Gaz. & press) | K15: Center tracked up Chesapeake Bay and through eastern PA; the NE edge raked NYC and the lower Hudson. | L15: Ludlum, Early American Hurricanes 1492–1870 (AMS, 1963), pp. 24–40 (verified, page images) | M15: https://hdl.handle.net/2027/mdp.39015002912718 | N15: C | O15: N | P15: NYC hit confirmed; upper-Hudson extent not documented. | Q15: 1769-09-08 | R15: =VALUE(LEFT(Q15,4)) | S15: =VALUE(MID(Q15,6,2)) | T15: =VALUE(RIGHT(Q15,2)) | U15: day | V15: Single-day event
A16: 15 | B16: 1775-09-03 | C16: 1775-09-03 | D16: =VALUE(LEFT(B16,4)) | E16: =INT((D16-1)/100)+1 | F16: Tropical cyclone | G16: The Independence Hurricane of 1775 | H16: Chesapeake / eastern PA; NE edge to NY | I16: Deadliest colonial hurricane (NC to Newfoundland); center up Chesapeake Bay then eastern PA (Hazel-1954 analog) | J16: Ludlum pp. 26–27 | K16: Track inland; the register keeps it as a major regional-adjacent storm. NY-specific damage not documented in these pages. | L16: Ludlum, Early American Hurricanes 1492–1870 (AMS, 1963), pp. 24–40 (verified, page images) | M16: https://hdl.handle.net/2027/mdp.39015002912718 | N16: C | O16: N | P16: Included for scale; no direct NY report. | Q16: 1775-09-03 | R16: =VALUE(LEFT(Q16,4)) | S16: =VALUE(MID(Q16,6,2)) | T16: =VALUE(RIGHT(Q16,2)) | U16: day | V16: Single-day event
A17: 16 | B17: 1775-12-24 | C17: 1775-12-24 | D17: =VALUE(LEFT(B17,4)) | E17: =INT((D17-1)/100)+1 | F17: Snowstorm | G17: Christmas Eve snowstorm 1775 – Knox's cannon train | H17: Albany / upper Hudson | I17: Knox reported a snowfall of two feet by Christmas Day; extreme cold and NW wind Dec 21; same storm system as the Carolina 'Snow Campaign' of Dec 23–25 | J17: Ludlum pp. 96, 147 (Knox letters) | K17: Knox sledded Ticonderoga's guns south along the Hudson; needed to cross the river four times between Lake George and Albany. | L17: Ludlum, Early American Winters I (page screenshots, verified) | N17: B | O17: Y | Q17: 1775-12-24 | R17: =VALUE(LEFT(Q17,4)) | S17: =VALUE(MID(Q17,6,2)) | T17: =VALUE(RIGHT(Q17,2)) | U17: day | V17: Single-day event
A18: 17 | B18: 1776-01-05 | C18: 1776-01-10 | D18: =VALUE(LEFT(B18,4)) | E18: =INT((D18-1)/100)+1 | F18: Thaw then freeze | G18: January 1776 thaw at Albany – Knox delayed, then Hudson bears the guns | H18: Albany / Claverack | I18: Jan 5: 'a cruel thaw hinders from crossing the Hudson'; near-continuous freezing from Jan 10 let the caravan cross and move east via Claverack over the Berkshires (Route 23) | J18: Ludlum pp. 96–97 (Knox to Washington, 5 Jan 1776) | K18: Framingham reached Jan 25; the artillery drove the British out of Boston Mar 17. | L18: Ludlum, Early American Winters I (page screenshots, verified) | N18: B | O18: Y | Q18: 1776-01-05 | R18: =VALUE(LEFT(Q18,4)) | S18: =VALUE(MID(Q18,6,2)) | T18: =VALUE(RIGHT(Q18,2)) | U18: days | V18: Multi-day event; anchored to first day
A19: 18 | B19: 1780-01-02 | C19: 1780-01-04 | D19: =VALUE(LEFT(B19,4)) | E19: =INT((D19-1)/100)+1 | F19: Blizzard | G19: Great Snowstorm of January 1780 (Hard Winter) | H19: NJ / Hudson Valley / New England | I19: 12 in at New Haven Jan 2–3 (Atwater); Washington Jan 6: 'eighteen inches, much drifted, roads impassable'; 42–48 in on the ground in S. CT after the 10-day series; drifts 6–12 ft | J19: Ludlum pp. 114–115 | K19: Second of three great storms (Dec 27–28, Jan 2–3, Jan 10); Stiles: more snow than the hard winter of 1740/41. | L19: Ludlum, Early American Winters I (page screenshots, verified) | M19: https://www.nps.gov/morr/learn/historyculture/hard-winter-news.htm | N19: B | O19: Y | P19: Ludlum: Jan 1780 = most persistently cold month in eastern US history. | Q19: 1780-01-02 | R19: =VALUE(LEFT(Q19,4)) | S19: =VALUE(MID(Q19,6,2)) | T19: =VALUE(RIGHT(Q19,2)) | U19: days | V19: Multi-day event; anchored to first day
A20: 19 | B20: 1780-01-07 | C20: 1780-02-21 | D20: =VALUE(LEFT(B20,4)) | E20: =INT((D20-1)/100)+1 | F20: Cold winter | G20: Hard Winter of 1779–80 – Hudson and harbor frozen | H20: Hudson Valley / NY Harbor | I20: Navigation stopped by ice Jan 7; East River on foot by Jan 14; Hudson on foot Jan 16–20; Staten Island→Manhattan on foot Jan 29; sleighs Feb 1; 86 sleighs with provisions Feb 6; thaw began Feb 11; ice rotting Feb 15; boats through the Narrows Feb 20, docks Feb 21 | J20: Hugh Gaine diary via Ludlum p. 115; Smith & Dohla diaries | K20: Only winter on record with NY waters closed to navigation for weeks; cannon dragged across to Staten Island. | L20: Ludlum, Early American Winters I (page screenshots, verified) | M20: https://www.nps.gov/morr/learn/historyculture/hard-winter-news.htm | N20: B | O20: Y | P20: Day-level chronology now complete for NYC; no Albany-specific dates yet. | Q20: 1780-01-16 | R20: =VALUE(LEFT(Q20,4)) | S20: =VALUE(MID(Q20,6,2)) | T20: =VALUE(RIGHT(Q20,2)) | U20: day | V20: Hudson first walked across at NYC (William Smith diary)
A21: 20 | B21: 1780-01-29 | C21: 1780-01-29 | D21: =VALUE(LEFT(B21,4)) | E21: =INT((D21-1)/100)+1 | F21: Arctic outbreak | G21: Nadir of the Hard Winter – Jan 29, 1780 | H21: Northeast | I21: Sunrise: Hartford −20°F (some sources −22°), Salem −17°F, NYC −16°F (unverified), ALBANY −20°F (Stiles, date not given) | J21: Ludlum pp. 79, 115 (Hartford sunrise table; Stiles register) | K21: Coldest morning of the coldest month on record; five consecutive sub-zero sunrises at Hartford Jan 25–29. | L21: Ludlum, Early American Winters I (page screenshots, verified) | N21: B | O21: Y | Q21: 1780-01-29 | R21: =VALUE(LEFT(Q21,4)) | S21: =VALUE(MID(Q21,6,2)) | T21: =VALUE(RIGHT(Q21,2)) | U21: day | V21: Single-day event
A22: 21 | B22: 1780-11-01 | C22: 1780-11-11 | D22: =VALUE(LEFT(B22,4)) | E22: =INT((D22-1)/100)+1 | F22: Early freeze | G22: Early freeze-up of the Hudson at Albany, Nov 1780 | H22: Albany / Middle States | I22: Deep snow Nov 1 over the Middle States; Hudson frozen at Albany Nov 11 – 'an unusually early date' | J22: Ludlum p. 134 (E. Stiles diary) | K22: Earliest documented freeze-up of the Hudson at Albany in the register. | L22: Ludlum, Early American Winters I (page screenshots, verified) | N22: B | O22: Y | Q22: 1780-11-11 | R22: =VALUE(LEFT(Q22,4)) | S22: =VALUE(MID(Q22,6,2)) | T22: =VALUE(RIGHT(Q22,2)) | U22: day | V22: Freeze-up date at Albany
A23: 22 | B23: 1781-01-22 | C23: 1781-01-23 | D23: =VALUE(LEFT(B23,4)) | E23: =INT((D23-1)/100)+1 | F23: Coastal storm / wind | G23: Great coastal storm of January 1781 | H23: NYC / Hudson Valley / New England | I23: NYC: heavy rain then snow, ~9 in; chimneys and trees blown down, people killed by falling chimneys; 'severest that has been felt here for many years' | J23: Ludlum pp. 134–135 (F. Mackenzie diary) | K23: Four naval vessels wrecked at Gardiners Island; 74-gun ship lost at Newport; prodigious inland snow (8 ft on the level claimed in NE Connecticut, unconfirmed). | L23: Ludlum, Early American Winters I (page screenshots, verified) | N23: B | O23: Y | Q23: 1781-01-22 | R23: =VALUE(LEFT(Q23,4)) | S23: =VALUE(MID(Q23,6,2)) | T23: =VALUE(RIGHT(Q23,2)) | U23: days | V23: Multi-day event; anchored to first day
A24: 23 | B24: 1783-10-18 | C24: 1783-10-19 | D24: =VALUE(LEFT(B24,4)) | E24: =INT((D24-1)/100)+1 | F24: Tropical remnant / snow / flood | G24: October 1783 storms – NY & New England | H24: New Brunswick NJ / New Haven / Goshen CT / VT | I24: 2nd of the Oct 1783 storms: mid-Oct snowfall to the shores of LI Sound; snow in Goshen CT and adjacent towns; VT height-of-land 6–8 in; Windsor VT 'greatest flood ever known since settlement' Oct 22 | J24: Ludlum p. 29 (Penna. papers, Vt. Journal) | K24: A cold-air-charged coastal storm that put snow on the CT Valley hills and caused the worst VT flood to that date; the Helderbergs likely saw the same snow. | L24: Ludlum, Early American Hurricanes 1492–1870 (AMS, 1963), pp. 24–40 (verified, page images) | M24: https://hdl.handle.net/2027/mdp.39015002912718 | N24: C | O24: Y | P24: Snow reached LI Sound hills; western extent (Helderbergs) inferred. | Q24: 1783-10-18 | R24: =VALUE(LEFT(Q24,4)) | S24: =VALUE(MID(Q24,6,2)) | T24: =VALUE(RIGHT(Q24,2)) | U24: days | V24: Second storm Oct 18–19; anchored to first day
A25: 24 | B25: 1783-12-30 | C25: 1783-12-31 | D25: =VALUE(LEFT(B25,4)) | E25: =INT((D25-1)/100)+1 | F25: Coastal storm | G25: Year-end storm of 1783 (Long Winter) | H25: NJ / NYC / Hudson Valley | I25: 20 in at Morristown Dec 30–31 'almost the same date as four years earlier'; Trappe PA 'uncommonly deep' | J25: Ludlum p. 65 (Joseph Lewis diary) | K25: Opened the Long Winter of 1783–84; greatest seasonal snowfall known in northern NJ. | L25: Ludlum, Early American Winters I (page screenshots, verified) | N25: B | O25: Y | Q25: 1783-12-30 | R25: =VALUE(LEFT(Q25,4)) | S25: =VALUE(MID(Q25,6,2)) | T25: =VALUE(RIGHT(Q25,2)) | U25: days | V25: Multi-day event; anchored to first day
A26: 25 | B26: 1784-02-10 | C26: 1784-02-17 | D26: =VALUE(LEFT(B26,4)) | E26: =INT((D26-1)/100)+1 | F26: Arctic outbreak | G26: February 1784 cold – the Long Winter | H26: Interior New England / NYC | I26: Hartford ≤ −12°F on 8 consecutive mornings Feb 10–17 (−20° Feb 14); New Haven −10° Feb 10; the Narrows choked with ice; Baltimore closed Jan 2–Mar 25, 16 days longer than 1780 | J26: Ludlum p. 65 (Webster / Amer. Jour. Sci.) | K26: Longest spell of sub-zero readings on record in southern New England; 1784 remembered by mariners as their toughest ice season. | L26: Ludlum, Early American Winters I (page screenshots, verified) | N26: B | O26: Y | P26: Albany value not given; likely colder. | Q26: 1784-02-10 | R26: =VALUE(LEFT(Q26,4)) | S26: =VALUE(MID(Q26,6,2)) | T26: =VALUE(RIGHT(Q26,2)) | U26: days | V26: Multi-day event; anchored to first day
A27: 26 | B27: 1788-08-19 | C27: 1788-08-19 | D27: =VALUE(LEFT(B27,4)) | E27: =INT((D27-1)/100)+1 | F27: Tropical cyclone / severe wind | G27: The Hurricane of August 19, 1788 – over the Hudson Highlands | H27: Hudson River highlands (Bear Mtn) / Berkshires / Hillsdale, Columbia Co. / Hudson / Poughkeepsie | I27: Small, fast (~45 mph) intense storm; ~50-mi-wide path of 75+ mph winds tracked over the Hudson River highlands near Bear Mountain into the Berkshires; Hillsdale NY first-hand account of a violent NW hurricane, streams to torrents, pines crushing houses; Poughkeepsie oaks down, creeks took bridges; Hudson 48-hr flood, mills carried off between Hudson and Albany | J27: Ludlum pp. 30–34 (Hudson Weekly Gazette, Country Journal, Daily Adv.) | K27: The most directly relevant early storm in the whole volume: its damage swath ran up the Hudson through Columbia and Dutchess counties. Reached to within the register's core. Ludlum debates hurricane vs. tornado vs. squall line and concludes hurricane. | L27: Ludlum, Early American Hurricanes 1492–1870 (AMS, 1963), pp. 24–40 (verified, page images) | M27: https://hdl.handle.net/2027/mdp.39015002912718 | N27: B | O27: Y | P27: Hillsdale (Columbia Co.) is ~20 mi from Westerlo; Hudson & Poughkeepsie flooding documented. Standout row from this batch. | Q27: 1788-08-19 | R27: =VALUE(LEFT(Q27,4)) | S27: =VALUE(MID(Q27,6,2)) | T27: =VALUE(RIGHT(Q27,2)) | U27: day | V27: Single-day event
A28: 27 | B28: 1789-01-30 | C28: 1789-02-02 | D28: =VALUE(LEFT(B28,4)) | E28: =INT((D28-1)/100)+1 | F28: Arctic outbreak | G28: February 2, 1789 – Albany's earliest instrumental extreme | H28: Albany / Hartford / New Haven | I28: Albany −24°F Feb 2, 'colder by 6° than ever known' (weather book at the museum opposite Denniston's tavern, Green Street); Hartford −28°F, 4° below anything known; snow half a foot Jan 30 | J28: The Annual Register (Albany, 1849) p. 329, via Ludlum p. 79 | K28: Earliest dated thermometer reading for Albany in the register; Stiles notes it as one of three notable cold days of his lifetime (Feb 5). | L28: Ludlum, Early American Winters I (page screenshots, verified) | N28: B | O28: Y | P28: Albany had a thermometer by Jan 1772. NB: the 42-year freeze notice (Amer. Quar. Jour. 1845) is headed 'From the Albany Daily Advertiser', not the New York Daily Advertiser as Ludlum's footnote says. | Q28: 1789-01-30 | R28: =VALUE(LEFT(Q28,4)) | S28: =VALUE(MID(Q28,6,2)) | T28: =VALUE(RIGHT(Q28,2)) | U28: days | V28: Multi-day event; anchored to first day
A29: 28 | B29: 1795-08-03 | C29: 1795-08-03 | D29: =VALUE(LEFT(B29,4)) | E29: =INT((D29-1)/100)+1 | F29: Tropical cyclone | G29: August 1795 storm – NYC fringe | H29: NYC / lower Hudson | I29: Henry Laight, NYC: 'a very heavy gale of wind and a great deal of rain from the East' Aug 3 | J29: Ludlum p. 34 (Laight Ms.) | K29: Twin NC hurricanes; only the northern fringe reached NYC. Minor for the region. | L29: Ludlum, Early American Hurricanes 1492–1870 (AMS, 1963), pp. 24–40 (verified, page images) | M29: https://hdl.handle.net/2027/mdp.39015002912718 | N29: C | O29: N | P29: NYC fringe only. | Q29: 1795-08-03 | R29: =VALUE(LEFT(Q29,4)) | S29: =VALUE(MID(Q29,6,2)) | T29: =VALUE(RIGHT(Q29,2)) | U29: day | V29: Single-day event
A30: 29 | B30: 1796-11-28 | C30: 1797-01-12 | D30: =VALUE(LEFT(B30,4)) | E30: =INT((D30-1)/100)+1 | F30: Cold winter | G30: Early severe winter 1796–97 | H30: Albany | I30: River closed Nov 28; intensely cold Dec 23–24, mercury at zero AM | J30: Albany freeze notice | K30: Early hard winter, severe to mid-January. | L30: Albany Daily Advertiser, "Notices of the Winters at New York for the last forty-two years… dates at which the Hudson was frozen or obstructed or closed by ice at Albany," repr. American Quarterly Journal of Agriculture and Science 1 (1845) pp. 347–350 (verified, page images) | M30: https://archive.org/details/americanquarterl00slsn | N30: B | O30: Y | Q30: 1796-12-20 | R30: =VALUE(LEFT(Q30,4)) | S30: =VALUE(MID(Q30,6,2)) | T30: =VALUE(RIGHT(Q30,2)) | U30: month | V30: Anchored to mid-point of a multi-week window
A31: 30 | B31: 1797-11-23 | C31: 1798-02-28 | D31: =VALUE(LEFT(B31,4)) | E31: =INT((D31-1)/100)+1 | F31: Cold winter | G31: Long severe winter 1797–98 | H31: Albany | I31: River closed Nov 23; lowest 2°F above zero | J31: Albany freeze notice | K31: Very early, long and severe; brief January thaw. | L31: Albany Daily Advertiser, "Notices of the Winters at New York for the last forty-two years… dates at which the Hudson was frozen or obstructed or closed by ice at Albany," repr. American Quarterly Journal of Agriculture and Science 1 (1845) pp. 347–350 (verified, page images) | M31: https://archive.org/details/americanquarterl00slsn | N31: B | O31: Y | Q31: 1798-01-10 | R31: =VALUE(LEFT(Q31,4)) | S31: =VALUE(MID(Q31,6,2)) | T31: =VALUE(RIGHT(Q31,2)) | U31: season | V31: Anchored to mid-point of a season-scale window
A32: 31 | B32: 1800-01-01 | C32: 2026-12-31 | D32: =VALUE(LEFT(B32,4)) | E32: =INT((D32-1)/100)+1 | F32: Sinkhole / karst | G32: Helderberg–Cobleskill karst (standing hazard) | H32: Knox, Berne, Clarksville, Cobleskill plateau | I32: Largest karst drainage in the Northeast; Cobleskill Creek loses most flow underground where it crosses the Coeymans Limestone | J32: none | K32: Context row: sinkholes and swallets are a permanent feature of the plateau; discrete collapse events are rarely reported. | L32: NYSGA 1991 field guide | M32: https://www.nysga-online.org/wp-content/uploads/2019/06/NYSGA-1991-A6-Interaction-Between-Karst-and-Glaciation-in-the-Helderberg-Plateau-Schoharie-and-Albany-Counties-New-York.pdf | N32: B | O32: Y | P32: Context row, not an event. | Q32: 1975-05-15 | R32: =VALUE(LEFT(Q32,4)) | S32: =VALUE(MID(Q32,6,2)) | T32: =VALUE(RIGHT(Q32,2)) | U32: year | V32: Context row – do not plot as a point
A33: 32 | B33: 1801-12-01 | C33: 1802-01-31 | D33: =VALUE(LEFT(B33,4)) | E33: =INT((D33-1)/100)+1 | F33: Mild winter | G33: Open winter of 1801–02 | H33: Albany / New Haven | I33: At Albany no ice on the Hudson strong enough to bear a team; only 1.25 in snow Dec–Jan; violets blooming at New Haven in January | J33: Ludlum p. 165 | K33: Least wintry season since the Revolution – a useful counter-example for the timeline. | L33: Ludlum, Early American Winters I (page screenshots, verified) | N33: B | O33: Y | Q33: 1802-01-15 | R33: =VALUE(LEFT(Q33,4)) | S33: =VALUE(MID(Q33,6,2)) | T33: =VALUE(RIGHT(Q33,2)) | U33: season | V33: Mid-winter; counter-example row
A34: 33 | B34: 1802-02-22 | C34: 1802-02-24 | D34: =VALUE(LEFT(B34,4)) | E34: =INT((D34-1)/100)+1 | F34: Nor'easter | G34: Great coastal storm and deep snow of Feb 1802 | H34: Hudson Valley / New England | I34: Snow reached Poughkeepsie 0400 and Albany just before daybreak Feb 22; 4+ ft at Rutland MA, 3.5 ft at Worcester; drifts 6–10 ft at Portsmouth | J34: Ludlum pp. 165–166 (Annals of Albany 3, 319) | K34: Dwight rated it equal to the 1717 storms; three East-Indiamen wrecked at Cape Cod, 9 dead. | L34: Ludlum, Early American Winters I (page screenshots, verified) | N34: B | O34: Y | P34: Albany depth not given – Annals of Albany vol. 3 p. 319 has it. | Q34: 1802-02-22 | R34: =VALUE(LEFT(Q34,4)) | S34: =VALUE(MID(Q34,6,2)) | T34: =VALUE(RIGHT(Q34,2)) | U34: days | V34: Multi-day event; anchored to first day
A35: 34 | B35: 1803-05-06 | C35: 1803-05-08 | D35: =VALUE(LEFT(B35,4)) | E35: =INT((D35-1)/100)+1 | F35: Late-season snow / frost | G35: May 1803 snow and frost | H35: Hudson (Columbia Co.) / Poughkeepsie / cut-off near Albany | I35: Hudson: severe frost Fri night May 6, 'considerable fall of snow' Sun May 8; Poughkeepsie: several inches, sleighs in the streets; snow canopy did not reach northern NY | J35: Ludlum p. 167 (The Balance, Hudson, 10 May 1803) | K35: First measurable May snow at seaboard locations since 1774; trees in leaf, apple in blossom. | L35: Ludlum, Early American Winters I (page screenshots, verified) | N35: B | O35: Y | P35: Cut-off line 'close to Albany' – Helderbergs almost certainly had snow. | Q35: 1803-05-06 | R35: =VALUE(LEFT(Q35,4)) | S35: =VALUE(MID(Q35,6,2)) | T35: =VALUE(RIGHT(Q35,2)) | U35: days | V35: Multi-day event; anchored to first day
A36: 35 | B36: 1804-02-23 | C36: 1804-03-05 | D36: =VALUE(LEFT(B36,4)) | E36: =INT((D36-1)/100)+1 | F36: Snowstorms | G36: Three snowstorms in one week – late winter 1804 | H36: Hudson Valley / Albany / New England | I36: Around Albany snow lay 3 ft on the level March 5; Hudson (Balance): average depth 'upwards of two feet' after the Fri Mar 2 storm; three mails overdue from NYC | J36: Ludlum pp. 168–169 (Annals of Albany 3, 327; Hudson Balance 6 Mar 1804) | K36: 'More snow than since 1780'; fodder scarce after the previous summer's drought and many cattle died in the interior. | L36: Ludlum, Early American Winters I (page screenshots, verified) | N36: B | O36: Y | Q36: 1804-03-02 | R36: =VALUE(LEFT(Q36,4)) | S36: =VALUE(MID(Q36,6,2)) | T36: =VALUE(RIGHT(Q36,2)) | U36: day | V36: Friday storm reported by the Hudson Balance
A37: 36 | B37: 1804-10-09 | C37: 1804-10-09 | D37: =VALUE(LEFT(B37,4)) | E37: =INT((D37-1)/100)+1 | F37: Tropical cyclone / early snow | G37: New England's Snow Hurricane of 1804 (full account) | H37: NYC / Poughkeepsie / Hudson / Catskills / Berkshires | I37: Center passed just W of NYC, S of Poughkeepsie; Hudson Valley lashed at Poughkeepsie & Hudson (main force from the N, 'violence not experienced since settlement'); leaf-on snow: Catskills up to 18 in, Berkshires 24–30 in, Goshen CT 12 in; heavy snow + hurricane wind wrecked orchards and sugar groves | J37: Ludlum pp. 35–38 (NY Post, Md. Gaz., Vt. Journal) | K37: This is the FULL account of the 1804 Snow Hurricane the register already listed. Confirms Catskill 18-inch leaf-on snow and severe Hudson Valley wind. Upgrades the existing row's detail. | L37: Ludlum, Early American Hurricanes 1492–1870 (AMS, 1963), pp. 24–40 (verified, page images) | M37: https://hdl.handle.net/2027/mdp.39015002912718 | N37: A | O37: Y | P37: Supersedes/enriches the existing 1804 Snow Hurricane row; Catskills & Hudson Valley directly documented. | Q37: 1804-10-09 | R37: =VALUE(LEFT(Q37,4)) | S37: =VALUE(MID(Q37,6,2)) | T37: =VALUE(RIGHT(Q37,2)) | U37: day | V37: Single-day event
A38: 37 | B38: 1804-12-13 | C38: 1805-03-01 | D38: =VALUE(LEFT(B38,4)) | E38: =INT((D38-1)/100)+1 | F38: Cold winter | G38: Severe winter 1804–05 at Albany | H38: Albany | I38: River closed Dec 13; lowest 2°F above zero; deep snows, heavy rains, high winds; 'much distress among the poor' | J38: Albany freeze notice | K38: Confirms the Albany side of the 1805 severe winter (register already had the NYC 48-hr snow). | L38: Albany Daily Advertiser, "Notices of the Winters at New York for the last forty-two years… dates at which the Hudson was frozen or obstructed or closed by ice at Albany," repr. American Quarterly Journal of Agriculture and Science 1 (1845) pp. 347–350 (verified, page images) | M38: https://archive.org/details/americanquarterl00slsn | N38: B | O38: Y | Q38: 1805-01-21 | R38: =VALUE(LEFT(Q38,4)) | S38: =VALUE(MID(Q38,6,2)) | T38: =VALUE(RIGHT(Q38,2)) | U38: season | V38: Anchored to mid-point of a season-scale window
A39: 38 | B39: 1805-01-22 | C39: 1805-01-23 | D39: =VALUE(LEFT(B39,4)) | E39: =INT((D39-1)/100)+1 | F39: Cold snap / river ice | G39: Hudson crossed on foot at NYC, Jan 1805 | H39: NYC / lower Hudson | I39: Extreme cold Jan 22 (wood $8/load); 'several persons crossed the Hudson from the State Prison to Hoboken' Jan 22–23 | J39: Ludlum p. 171 (Henry Laight notes) | K39: Winter 1804–05 'the most rigorous as a whole since 1780'. | L39: Ludlum, Early American Winters I (page screenshots, verified) | N39: B | O39: Y | Q39: 1805-01-22 | R39: =VALUE(LEFT(Q39,4)) | S39: =VALUE(MID(Q39,6,2)) | T39: =VALUE(RIGHT(Q39,2)) | U39: days | V39: Multi-day event; anchored to first day
A40: 39 | B40: 1805-01-26 | C40: 1805-01-28 | D40: =VALUE(LEFT(B40,4)) | E40: =INT((D40-1)/100)+1 | F40: Snowstorm | G40: The 48-hour snow at New York, Jan 1805 | H40: NYC / lower Hudson | I40: 20–24 in on top of existing cover; snow Jan 26 evening → Jan 28 evening without interruption; Jan 1805 snowiest month of early record at NYC | J40: Ludlum pp. 170–172 | K40: Streets impassable even for sleighs; Jan 1805 snow 'about three feet deep' (Webster). | L40: Ludlum, Early American Winters I (page screenshots, verified) | N40: B | O40: Y | Q40: 1805-01-26 | R40: =VALUE(LEFT(Q40,4)) | S40: =VALUE(MID(Q40,6,2)) | T40: =VALUE(RIGHT(Q40,2)) | U40: days | V40: Multi-day event; anchored to first day
...

Sheet Wind & Tornadoes
A1: Date | B1: Time (local) | C1: County | D1: Place / path | E1: Type | F1: Rating / peak wind | G1: Path length (mi) | H1: Width (yd) | I1: Deaths | J1: Injuries | K1: Start lat | L1: Start lon | M1: End lat | N1: End lon | O1: Dist. from Westerlo, start (mi) | P1: Dist. from Westerlo, end (mi) | Q1: Nearest point (mi) | R1: Within radius? | S1: Source | T1: Confidence | U1: Notes
A2: 1821-07-08 | C2: Columbia | D2: Columbia Co. (Grazulis) | E2: Tornado | F2: FU | G2: 5.5 | H2: 100 | I2: 0 | J2: 0 | K2: 42.25 | L2: -73.62 | O2: =IF(OR(K2="",L2=""),"",ROUND(3959*ACOS(MIN(1,SIN(RADIANS(README!$B$3))*SIN(RADIANS(K2))+COS(RADIANS(README!$B$3))*COS(RADIANS(K2))*COS(RADIANS(L2-README!$B$4)))),1)) | P2: =IF(OR(M2="",N2=""),"",ROUND(3959*ACOS(MIN(1,SIN(RADIANS(README!$B$3))*SIN(RADIANS(M2))+COS(RADIANS(README!$B$3))*COS(RADIANS(M2))*COS(RADIANS(N2-README!$B$4)))),1)) | Q2: =IF(O2="","",IF(P2="",O2,MIN(O2,P2))) | R2: =IF(Q2="","n/a",IF(Q2<=README!$B$5,"Yes","No")) | S2: Grazulis via tornadopath | T2: C | U2: County centroid approx; pre-1950 F2+/deadly only
A3: 1867-06-16 | C3: Columbia | D3: Columbia Co. (Grazulis) | E3: Tornado | F3: FU | I3: 0 | J3: 0 | K3: 42.25 | L3: -73.62 | O3: =IF(OR(K3="",L3=""),"",ROUND(3959*ACOS(MIN(1,SIN(RADIANS(README!$B$3))*SIN(RADIANS(K3))+COS(RADIANS(README!$B$3))*COS(RADIANS(K3))*COS(RADIANS(L3-README!$B$4)))),1)) | P3: =IF(OR(M3="",N3=""),"",ROUND(3959*ACOS(MIN(1,SIN(RADIANS(README!$B$3))*SIN(RADIANS(M3))+COS(RADIANS(README!$B$3))*COS(RADIANS(M3))*COS(RADIANS(N3-README!$B$4)))),1)) | Q3: =IF(O3="","",IF(P3="",O3,MIN(O3,P3))) | R3: =IF(Q3="","n/a",IF(Q3<=README!$B$5,"Yes","No")) | S3: Grazulis via tornadopath | T3: C | U3: County centroid approx
A4: 1875-08-22 | B4: 16:56 | C4: Albany | D4: Albany Co. (Grazulis) | E4: Tornado | F4: F1 | I4: 2 | J4: 0 | K4: 42.6 | L4: -73.97 | O4: =IF(OR(K4="",L4=""),"",ROUND(3959*ACOS(MIN(1,SIN(RADIANS(README!$B$3))*SIN(RADIANS(K4))+COS(RADIANS(README!$B$3))*COS(RADIANS(K4))*COS(RADIANS(L4-README!$B$4)))),1)) | P4: =IF(OR(M4="",N4=""),"",ROUND(3959*ACOS(MIN(1,SIN(RADIANS(README!$B$3))*SIN(RADIANS(M4))+COS(RADIANS(README!$B$3))*COS(RADIANS(M4))*COS(RADIANS(N4-README!$B$4)))),1)) | Q4: =IF(O4="","",IF(P4="",O4,MIN(O4,P4))) | R4: =IF(Q4="","n/a",IF(Q4<=README!$B$5,"Yes","No")) | S4: Grazulis via tornadopath | T4: C | U4: 2 fatalities; county centroid approx
A5: 1877-07-16 | B5: 16:56 | C5: Columbia | D5: Columbia Co. (Grazulis) | E5: Tornado | F5: F1 | I5: 0 | J5: 0 | K5: 42.25 | L5: -73.62 | O5: =IF(OR(K5="",L5=""),"",ROUND(3959*ACOS(MIN(1,SIN(RADIANS(README!$B$3))*SIN(RADIANS(K5))+COS(RADIANS(README!$B$3))*COS(RADIANS(K5))*COS(RADIANS(L5-README!$B$4)))),1)) | P5: =IF(OR(M5="",N5=""),"",ROUND(3959*ACOS(MIN(1,SIN(RADIANS(README!$B$3))*SIN(RADIANS(M5))+COS(RADIANS(README!$B$3))*COS(RADIANS(M5))*COS(RADIANS(N5-README!$B$4)))),1)) | Q5: =IF(O5="","",IF(P5="",O5,MIN(O5,P5))) | R5: =IF(Q5="","n/a",IF(Q5<=README!$B$5,"Yes","No")) | S5: Grazulis via tornadopath | T5: C | U5: County centroid approx
A6: 1878-07-21 | B6: 18:20 | C6: Albany | D6: Albany Co. (Grazulis) | E6: Tornado | F6: F2 | G6: 0.5 | H6: 50 | I6: 0 | J6: 0 | K6: 42.6 | L6: -73.97 | O6: =IF(OR(K6="",L6=""),"",ROUND(3959*ACOS(MIN(1,SIN(RADIANS(README!$B$3))*SIN(RADIANS(K6))+COS(RADIANS(README!$B$3))*COS(RADIANS(K6))*COS(RADIANS(L6-README!$B$4)))),1)) | P6: =IF(OR(M6="",N6=""),"",ROUND(3959*ACOS(MIN(1,SIN(RADIANS(README!$B$3))*SIN(RADIANS(M6))+COS(RADIANS(README!$B$3))*COS(RADIANS(M6))*COS(RADIANS(N6-README!$B$4)))),1)) | Q6: =IF(O6="","",IF(P6="",O6,MIN(O6,P6))) | R6: =IF(Q6="","n/a",IF(Q6<=README!$B$5,"Yes","No")) | S6: Grazulis via tornadopath | T6: C | U6: County centroid approx
A7: 1879-07-16 | B7: 19:30 | C7: Greene | D7: Greene Co. (Grazulis) | E7: Tornado | F7: F2 | I7: 0 | J7: 0 | K7: 42.28 | L7: -74.12 | O7: =IF(OR(K7="",L7=""),"",ROUND(3959*ACOS(MIN(1,SIN(RADIANS(README!$B$3))*SIN(RADIANS(K7))+COS(RADIANS(README!$B$3))*COS(RADIANS(K7))*COS(RADIANS(L7-README!$B$4)))),1)) | P7: =IF(OR(M7="",N7=""),"",ROUND(3959*ACOS(MIN(1,SIN(RADIANS(README!$B$3))*SIN(RADIANS(M7))+COS(RADIANS(README!$B$3))*COS(RADIANS(M7))*COS(RADIANS(N7-README!$B$4)))),1)) | Q7: =IF(O7="","",IF(P7="",O7,MIN(O7,P7))) | R7: =IF(Q7="","n/a",IF(Q7<=README!$B$5,"Yes","No")) | S7: Grazulis via tornadopath | T7: C | U7: County centroid approx
A8: 1950-11-24 | B8: 18:30 | C8: Albany | D8: Albany (Great Appalachian Storm) | E8: Synoptic windstorm | F8: 83 mph gust | K8: 42.75 | L8: -73.8 | O8: =IF(OR(K8="",L8=""),"",ROUND(3959*ACOS(MIN(1,SIN(RADIANS(README!$B$3))*SIN(RADIANS(K8))+COS(RADIANS(README!$B$3))*COS(RADIANS(K8))*COS(RADIANS(L8-README!$B$4)))),1)) | P8: =IF(OR(M8="",N8=""),"",ROUND(3959*ACOS(MIN(1,SIN(RADIANS(README!$B$3))*SIN(RADIANS(M8))+COS(RADIANS(README!$B$3))*COS(RADIANS(M8))*COS(RADIANS(N8-README!$B$4)))),1)) | Q8: =IF(O8="","",IF(P8="",O8,MIN(O8,P8))) | R8: =IF(Q8="","n/a",IF(Q8<=README!$B$5,"Yes","No")) | S8: NWS Albany – Past Weather Events (weather.gov/aly/pastevents) | T8: A | U8: Strongest gust ever at Albany
A9: 1960-06-24 | B9: 17:30 | C9: Schenectady | D9: Schenectady Co. | E9: Tornado | F9: F3 | I9: 0 | J9: 9 | K9: 42.8 | L9: -73.88 | M9: 42.92 | N9: -73.73 | O9: =IF(OR(K9="",L9=""),"",ROUND(3959*ACOS(MIN(1,SIN(RADIANS(README!$B$3))*SIN(RADIANS(K9))+COS(RADIANS(README!$B$3))*COS(RADIANS(K9))*COS(RADIANS(L9-README!$B$4)))),1)) | P9: =IF(OR(M9="",N9=""),"",ROUND(3959*ACOS(MIN(1,SIN(RADIANS(README!$B$3))*SIN(RADIANS(M9))+COS(RADIANS(README!$B$3))*COS(RADIANS(M9))*COS(RADIANS(N9-README!$B$4)))),1)) | Q9: =IF(O9="","",IF(P9="",O9,MIN(O9,P9))) | R9: =IF(Q9="","n/a",IF(Q9<=README!$B$5,"Yes","No")) | S9: Tornado Project (Grazulis) NY county list 1950–2012 | T9: A | U9: ~$25M
A10: 1964-12-04 | C10: Region | D10: East-central NY | E10: Ice storm (not wind) | F10: 1.5 in ice | K10: 42.75 | L10: -73.8 | O10: =IF(OR(K10="",L10=""),"",ROUND(3959*ACOS(MIN(1,SIN(RADIANS(README!$B$3))*SIN(RADIANS(K10))+COS(RADIANS(README!$B$3))*COS(RADIANS(K10))*COS(RADIANS(L10-README!$B$4)))),1)) | P10: =IF(OR(M10="",N10=""),"",ROUND(3959*ACOS(MIN(1,SIN(RADIANS(README!$B$3))*SIN(RADIANS(M10))+COS(RADIANS(README!$B$3))*COS(RADIANS(M10))*COS(RADIANS(N10-README!$B$4)))),1)) | Q10: =IF(O10="","",IF(P10="",O10,MIN(O10,P10))) | R10: =IF(Q10="","n/a",IF(Q10<=README!$B$5,"Yes","No")) | S10: NWS Albany – Past Weather Events (weather.gov/aly/pastevents) | T10: A | U10: Listed for tree-damage comparison
A11: 1973-06-30 | B11: 16:15 | C11: Albany | D11: SW Albany Co. – Westerlo/Rensselaerville area | E11: Tornado | F11: F1 | G11: 1.3 | H11: 10 | I11: 0 | J11: 2 | K11: 42.55 | L11: -74.05 | O11: =IF(OR(K11="",L11=""),"",ROUND(3959*ACOS(MIN(1,SIN(RADIANS(README!$B$3))*SIN(RADIANS(K11))+COS(RADIANS(README!$B$3))*COS(RADIANS(K11))*COS(RADIANS(L11-README!$B$4)))),1)) | P11: =IF(OR(M11="",N11=""),"",ROUND(3959*ACOS(MIN(1,SIN(RADIANS(README!$B$3))*SIN(RADIANS(M11))+COS(RADIANS(README!$B$3))*COS(RADIANS(M11))*COS(RADIANS(N11-README!$B$4)))),1)) | Q11: =IF(O11="","",IF(P11="",O11,MIN(O11,P11))) | R11: =IF(Q11="","n/a",IF(Q11<=README!$B$5,"Yes","No")) | S11: Tornado Project (Grazulis) NY county list 1950–2012 | T11: A | U11: Touchdown ~2 mi from Westerlo hamlet
A12: 1973-08-28 | B12: 10:00 | C12: Rensselaer | D12: Rensselaer Co. | E12: Tornado | F12: F2 | G12: 2.3 | H12: 83 | I12: 0 | J12: 1 | K12: 42.9 | L12: -73.55 | M12: 42.92 | N12: -73.48 | O12: =IF(OR(K12="",L12=""),"",ROUND(3959*ACOS(MIN(1,SIN(RADIANS(README!$B$3))*SIN(RADIANS(K12))+COS(RADIANS(README!$B$3))*COS(RADIANS(K12))*COS(RADIANS(L12-README!$B$4)))),1)) | P12: =IF(OR(M12="",N12=""),"",ROUND(3959*ACOS(MIN(1,SIN(RADIANS(README!$B$3))*SIN(RADIANS(M12))+COS(RADIANS(README!$B$3))*COS(RADIANS(M12))*COS(RADIANS(N12-README!$B$4)))),1)) | Q12: =IF(O12="","",IF(P12="",O12,MIN(O12,P12))) | R12: =IF(Q12="","n/a",IF(Q12<=README!$B$5,"Yes","No")) | S12: Tornado Project (Grazulis) NY county list 1950–2012 | T12: A | U12: Same outbreak as Columbia F4
A13: 1973-08-28 | B13: 11:34 | C13: Columbia | D13: Stephentown area → MA | E13: Tornado | F13: F4 | G13: 3.4 | H13: 313 | I13: 0 | J13: 0 | K13: 42.42 | L13: -73.42 | M13: 42.37 | N13: -73.42 | O13: =IF(OR(K13="",L13=""),"",ROUND(3959*ACOS(MIN(1,SIN(RADIANS(README!$B$3))*SIN(RADIANS(K13))+COS(RADIANS(README!$B$3))*COS(RADIANS(K13))*COS(RADIANS(L13-README!$B$4)))),1)) | P13: =IF(OR(M13="",N13=""),"",ROUND(3959*ACOS(MIN(1,SIN(RADIANS(README!$B$3))*SIN(RADIANS(M13))+COS(RADIANS(README!$B$3))*COS(RADIANS(M13))*COS(RADIANS(N13-README!$B$4)))),1)) | Q13: =IF(O13="","",IF(P13="",O13,MIN(O13,P13))) | R13: =IF(Q13="","n/a",IF(Q13<=README!$B$5,"Yes","No")) | S13: Tornado Project (Grazulis) NY county list 1950–2012 | T13: A | U13: First recorded F4 in NY
A14: 1974-06-16 | B14: 11:10 | C14: Greene→Saratoga | D14: Catskill → Saratoga Co. | E14: Tornado | F14: F3 | G14: 49.1 | I14: 0 | J14: 0 | K14: 42.25 | L14: -73.83 | M14: 42.92 | N14: -73.88 | O14: =IF(OR(K14="",L14=""),"",ROUND(3959*ACOS(MIN(1,SIN(RADIANS(README!$B$3))*SIN(RADIANS(K14))+COS(RADIANS(README!$B$3))*COS(RADIANS(K14))*COS(RADIANS(L14-README!$B$4)))),1)) | P14: =IF(OR(M14="",N14=""),"",ROUND(3959*ACOS(MIN(1,SIN(RADIANS(README!$B$3))*SIN(RADIANS(M14))+COS(RADIANS(README!$B$3))*COS(RADIANS(M14))*COS(RADIANS(N14-README!$B$4)))),1)) | Q14: =IF(O14="","",IF(P14="",O14,MIN(O14,P14))) | R14: =IF(Q14="","n/a",IF(Q14<=README!$B$5,"Yes","No")) | S14: Tornado Project (Grazulis) NY county list 1950–2012 | T14: A | U14: Long track through Greene, Albany, Saratoga
A15: 1974-08-27 | B15: 16:00 | C15: Rensselaer | D15: Rensselaer Co. | E15: Tornado | F15: F1 | H15: 33 | I15: 0 | J15: 0 | K15: 42.83 | L15: -73.5 | O15: =IF(OR(K15="",L15=""),"",ROUND(3959*ACOS(MIN(1,SIN(RADIANS(README!$B$3))*SIN(RADIANS(K15))+COS(RADIANS(README!$B$3))*COS(RADIANS(K15))*COS(RADIANS(L15-README!$B$4)))),1)) | P15: =IF(OR(M15="",N15=""),"",ROUND(3959*ACOS(MIN(1,SIN(RADIANS(README!$B$3))*SIN(RADIANS(M15))+COS(RADIANS(README!$B$3))*COS(RADIANS(M15))*COS(RADIANS(N15-README!$B$4)))),1)) | Q15: =IF(O15="","",IF(P15="",O15,MIN(O15,P15))) | R15: =IF(Q15="","n/a",IF(Q15<=README!$B$5,"Yes","No")) | S15: Tornado Project (Grazulis) NY county list 1950–2012 | T15: A
A16: 1975-09-20 | B16: 17:30 | C16: Ulster→Columbia | D16: Kingston area → Columbia Co. | E16: Tornado | F16: F1 | G16: 7.1 | H16: 167 | I16: 0 | J16: 3 | K16: 41.97 | L16: -74.07 | M16: 42.08 | N16: -73.82 | O16: =IF(OR(K16="",L16=""),"",ROUND(3959*ACOS(MIN(1,SIN(RADIANS(README!$B$3))*SIN(RADIANS(K16))+COS(RADIANS(README!$B$3))*COS(RADIANS(K16))*COS(RADIANS(L16-README!$B$4)))),1)) | P16: =IF(OR(M16="",N16=""),"",ROUND(3959*ACOS(MIN(1,SIN(RADIANS(README!$B$3))*SIN(RADIANS(M16))+COS(RADIANS(README!$B$3))*COS(RADIANS(M16))*COS(RADIANS(N16-README!$B$4)))),1)) | Q16: =IF(O16="","",IF(P16="",O16,MIN(O16,P16))) | R16: =IF(Q16="","n/a",IF(Q16<=README!$B$5,"Yes","No")) | S16: Tornado Project (Grazulis) NY county list 1950–2012 | T16: A
A17: 1976-02-02 | C17: Albany | D17: Albany (flash freeze) | E17: Synoptic windstorm | F17: 67 mph gust | I17: 2 | K17: 42.75 | L17: -73.8 | O17: =IF(OR(K17="",L17=""),"",ROUND(3959*ACOS(MIN(1,SIN(RADIANS(README!$B$3))*SIN(RADIANS(K17))+COS(RADIANS(README!$B$3))*COS(RADIANS(K17))*COS(RADIANS(L17-README!$B$4)))),1)) | P17: =IF(OR(M17="",N17=""),"",ROUND(3959*ACOS(MIN(1,SIN(RADIANS(README!$B$3))*SIN(RADIANS(M17))+COS(RADIANS(README!$B$3))*COS(RADIANS(M17))*COS(RADIANS(N17-README!$B$4)))),1)) | Q17: =IF(O17="","",IF(P17="",O17,MIN(O17,P17))) | R17: =IF(Q17="","n/a",IF(Q17<=README!$B$5,"Yes","No")) | S17: NWS Albany – Past Weather Events (weather.gov/aly/pastevents) | T17: A | U17: 2 fatalities regionally
A18: 1977-04-02 | B18: 17:00 | C18: Greene | D18: W. Greene Co. | E18: Tornado | F18: F1 | G18: 1.8 | H18: 33 | I18: 0 | J18: 0 | K18: 42.2 | L18: -74.22 | O18: =IF(OR(K18="",L18=""),"",ROUND(3959*ACOS(MIN(1,SIN(RADIANS(README!$B$3))*SIN(RADIANS(K18))+COS(RADIANS(README!$B$3))*COS(RADIANS(K18))*COS(RADIANS(L18-README!$B$4)))),1)) | P18: =IF(OR(M18="",N18=""),"",ROUND(3959*ACOS(MIN(1,SIN(RADIANS(README!$B$3))*SIN(RADIANS(M18))+COS(RADIANS(README!$B$3))*COS(RADIANS(M18))*COS(RADIANS(N18-README!$B$4)))),1)) | Q18: =IF(O18="","",IF(P18="",O18,MIN(O18,P18))) | R18: =IF(Q18="","n/a",IF(Q18<=README!$B$5,"Yes","No")) | S18: Tornado Project (Grazulis) NY county list 1950–2012 | T18: A
A19: 1978-07-10 | B19: 14:45 | C19: Columbia | D19: Columbia Co. | E19: Tornado | F19: F1 | G19: 0.7 | H19: 53 | I19: 0 | J19: 0 | K19: 42.17 | L19: -73.75 | O19: =IF(OR(K19="",L19=""),"",ROUND(3959*ACOS(MIN(1,SIN(RADIANS(README!$B$3))*SIN(RADIANS(K19))+COS(RADIANS(README!$B$3))*COS(RADIANS(K19))*COS(RADIANS(L19-README!$B$4)))),1)) | P19: =IF(OR(M19="",N19=""),"",ROUND(3959*ACOS(MIN(1,SIN(RADIANS(README!$B$3))*SIN(RADIANS(M19))+COS(RADIANS(README!$B$3))*COS(RADIANS(M19))*COS(RADIANS(N19-README!$B$4)))),1)) | Q19: =IF(O19="","",IF(P19="",O19,MIN(O19,P19))) | R19: =IF(Q19="","n/a",IF(Q19<=README!$B$5,"Yes","No")) | S19: Tornado Project (Grazulis) NY county list 1950–2012 | T19: A
A20: 1980-07-11 | B20: 15:00 | C20: Albany | D20: Albany Co. | E20: Tornado | F20: F0 | G20: 0.2 | H20: 133 | I20: 0 | J20: 0 | K20: 42.57 | L20: -73.97 | O20: =IF(OR(K20="",L20=""),"",ROUND(3959*ACOS(MIN(1,SIN(RADIANS(README!$B$3))*SIN(RADIANS(K20))+COS(RADIANS(README!$B$3))*COS(RADIANS(K20))*COS(RADIANS(L20-README!$B$4)))),1)) | P20: =IF(OR(M20="",N20=""),"",ROUND(3959*ACOS(MIN(1,SIN(RADIANS(README!$B$3))*SIN(RADIANS(M20))+COS(RADIANS(README!$B$3))*COS(RADIANS(M20))*COS(RADIANS(N20-README!$B$4)))),1)) | Q20: =IF(O20="","",IF(P20="",O20,MIN(O20,P20))) | R20: =IF(Q20="","n/a",IF(Q20<=README!$B$5,"Yes","No")) | S20: Tornado Project (Grazulis) NY county list 1950–2012 | T20: A
A21: 1984-05-12 | B21: 13:25 | C21: Albany | D21: N. Albany Co. (Berne/Knox area) | E21: Tornado | F21: F0 | H21: 10 | I21: 0 | J21: 13 | K21: 42.7 | L21: -74.03 | O21: =IF(OR(K21="",L21=""),"",ROUND(3959*ACOS(MIN(1,SIN(RADIANS(README!$B$3))*SIN(RADIANS(K21))+COS(RADIANS(README!$B$3))*COS(RADIANS(K21))*COS(RADIANS(L21-README!$B$4)))),1)) | P21: =IF(OR(M21="",N21=""),"",ROUND(3959*ACOS(MIN(1,SIN(RADIANS(README!$B$3))*SIN(RADIANS(M21))+COS(RADIANS(README!$B$3))*COS(RADIANS(M21))*COS(RADIANS(N21-README!$B$4)))),1)) | Q21: =IF(O21="","",IF(P21="",O21,MIN(O21,P21))) | R21: =IF(Q21="","n/a",IF(Q21<=README!$B$5,"Yes","No")) | S21: Tornado Project (Grazulis) NY county list 1950–2012 | T21: A | U21: 13 injuries
A22: 1986-10-01 | B22: 00:00 | C22: Delaware | D22: NE Delaware Co. | E22: Tornado | F22: F2 | I22: 0 | J22: 0 | K22: 42.28 | L22: -74.57 | O22: =IF(OR(K22="",L22=""),"",ROUND(3959*ACOS(MIN(1,SIN(RADIANS(README!$B$3))*SIN(RADIANS(K22))+COS(RADIANS(README!$B$3))*COS(RADIANS(K22))*COS(RADIANS(L22-README!$B$4)))),1)) | P22: =IF(OR(M22="",N22=""),"",ROUND(3959*ACOS(MIN(1,SIN(RADIANS(README!$B$3))*SIN(RADIANS(M22))+COS(RADIANS(README!$B$3))*COS(RADIANS(M22))*COS(RADIANS(N22-README!$B$4)))),1)) | Q22: =IF(O22="","",IF(P22="",O22,MIN(O22,P22))) | R22: =IF(Q22="","n/a",IF(Q22<=README!$B$5,"Yes","No")) | S22: Tornado Project (Grazulis) NY county list 1950–2012 | T22: A
A23: 1987-10-04 | C23: Region | D23: Leaf-on snowstorm (tree damage) | E23: Snow load (not wind) | K23: 42.75 | L23: -73.8 | O23: =IF(OR(K23="",L23=""),"",ROUND(3959*ACOS(MIN(1,SIN(RADIANS(README!$B$3))*SIN(RADIANS(K23))+COS(RADIANS(README!$B$3))*COS(RADIANS(K23))*COS(RADIANS(L23-README!$B$4)))),1)) | P23: =IF(OR(M23="",N23=""),"",ROUND(3959*ACOS(MIN(1,SIN(RADIANS(README!$B$3))*SIN(RADIANS(M23))+COS(RADIANS(README!$B$3))*COS(RADIANS(M23))*COS(RADIANS(N23-README!$B$4)))),1)) | Q23: =IF(O23="","",IF(P23="",O23,MIN(O23,P23))) | R23: =IF(Q23="","n/a",IF(Q23<=README!$B$5,"Yes","No")) | S23: NWS Albany – Past Weather Events (weather.gov/aly/pastevents) | T23: A | U23: Listed for tree-damage comparison
A24: 1989-07-10 | B24: 12:40 | C24: Montgomery→Greene | D24: Ames → Schoharie → Rensselaerville → East Durham | E24: Tornado family | F24: F4 | G24: 42 | H24: 1320 | I24: 0 | J24: 20 | K24: 42.83 | L24: -74.53 | M24: 42.38 | N24: -74.03 | O24: =IF(OR(K24="",L24=""),"",ROUND(3959*ACOS(MIN(1,SIN(RADIANS(README!$B$3))*SIN(RADIANS(K24))+COS(RADIANS(README!$B$3))*COS(RADIANS(K24))*COS(RADIANS(L24-README!$B$4)))),1)) | P24: =IF(OR(M24="",N24=""),"",ROUND(3959*ACOS(MIN(1,SIN(RADIANS(README!$B$3))*SIN(RADIANS(M24))+COS(RADIANS(README!$B$3))*COS(RADIANS(M24))*COS(RADIANS(N24-README!$B$4)))),1)) | Q24: =IF(O24="","",IF(P24="",O24,MIN(O24,P24))) | R24: =IF(Q24="","n/a",IF(Q24<=README!$B$5,"Yes","No")) | S24: Wikipedia / NWS / Grazulis | T24: A | U24: Only F4 in NY; brief touchdowns near Rensselaerville and Greenville; path within a few miles of Westerlo
A25: 1989-11-16 | B25: 13:30 | C25: Rensselaer | D25: Rensselaer Co. | E25: Tornado | F25: F0 | G25: 0.1 | H25: 17 | I25: 0 | J25: 0 | K25: 42.95 | L25: -73.43 | O25: =IF(OR(K25="",L25=""),"",ROUND(3959*ACOS(MIN(1,SIN(RADIANS(README!$B$3))*SIN(RADIANS(K25))+COS(RADIANS(README!$B$3))*COS(RADIANS(K25))*COS(RADIANS(L25-README!$B$4)))),1)) | P25: =IF(OR(M25="",N25=""),"",ROUND(3959*ACOS(MIN(1,SIN(RADIANS(README!$B$3))*SIN(RADIANS(M25))+COS(RADIANS(README!$B$3))*COS(RADIANS(M25))*COS(RADIANS(N25-README!$B$4)))),1)) | Q25: =IF(O25="","",IF(P25="",O25,MIN(O25,P25))) | R25: =IF(Q25="","n/a",IF(Q25<=README!$B$5,"Yes","No")) | S25: Tornado Project (Grazulis) NY county list 1950–2012 | T25: A | U25: Same day as Coldenham downburst
A26: 1990-04-28 | B26: 12:30 | C26: Greene | D26: Greene Co. | E26: Tornado | F26: F0 | G26: 0.2 | H26: 10 | I26: 0 | J26: 1 | K26: 42.2 | L26: -73.97 | O26: =IF(OR(K26="",L26=""),"",ROUND(3959*ACOS(MIN(1,SIN(RADIANS(README!$B$3))*SIN(RADIANS(K26))+COS(RADIANS(README!$B$3))*COS(RADIANS(K26))*COS(RADIANS(L26-README!$B$4)))),1)) | P26: =IF(OR(M26="",N26=""),"",ROUND(3959*ACOS(MIN(1,SIN(RADIANS(README!$B$3))*SIN(RADIANS(M26))+COS(RADIANS(README!$B$3))*COS(RADIANS(M26))*COS(RADIANS(N26-README!$B$4)))),1)) | Q26: =IF(O26="","",IF(P26="",O26,MIN(O26,P26))) | R26: =IF(Q26="","n/a",IF(Q26<=README!$B$5,"Yes","No")) | S26: Tornado Project (Grazulis) NY county list 1950–2012 | T26: A
A27: 1990-08-28 | B27: 19:30 | C27: Albany | D27: Bozenkill Rd, Knox (Peterson farm) | E27: Tornado | F27: F0 | G27: 0.3 | H27: 7 | I27: 0 | J27: 0 | K27: 42.75 | L27: -74.1 | O27: =IF(OR(K27="",L27=""),"",ROUND(3959*ACOS(MIN(1,SIN(RADIANS(README!$B$3))*SIN(RADIANS(K27))+COS(RADIANS(README!$B$3))*COS(RADIANS(K27))*COS(RADIANS(L27-README!$B$4)))),1)) | P27: =IF(OR(M27="",N27=""),"",ROUND(3959*ACOS(MIN(1,SIN(RADIANS(README!$B$3))*SIN(RADIANS(M27))+COS(RADIANS(README!$B$3))*COS(RADIANS(M27))*COS(RADIANS(N27-README!$B$4)))),1)) | Q27: =IF(O27="","",IF(P27="",O27,MIN(O27,P27))) | R27: =IF(Q27="","n/a",IF(Q27<=README!$B$5,"Yes","No")) | S27: Tornado Project (Grazulis) NY county list 1950–2012 | T27: A | U27: CONFIRMED — the 1990 Bozenkill Rd (Knox) tornado toppled Carl Peterson's silo, per Peterson himself (Altamont Enterprise 4 Mar 2010 & 29 May 2014). Peterson farm = recurring-disaster site: 1990 tornado (silo) + Feb 2010 snow-load barn collapse (70+ cows, 4 lost).
